<mujoco version="1.0">
	<compiler inertiafromgeom="true" maxjacobian="400"/>
	<default>
		<joint limtype="1" damping="2"/> 
		<geom contype="1" condim="3" friction=".7 .1 .1" rgba="0.4 0.5 .6 1" 
		softness="0.001" density="1000" colmask="1 1" mindist="0.002"/>
		<actuator range="-.3 .3"/>
	</default>
	<engine modelname="humanoid"  timestep="0.01" imperrreduce="0"	sclsoftness="0.1 0" />
	<world coordinate="local" angle="degree">
		<!--geom name="hf" pos="0 0 -1" size="4 4 .5" type="hfield" hfieldfile="my_height_field" hfielddir="true" colmask="1 0"  rgba="0.8 0.9 0.8 1" /-->
		<geom name="ground" type="plane" contype="1" softness="0.001" mindist="0.01" pos="0 0 0" colmask="1 0" size="4 4 4" rgba="0.9 0.9 0.9 1"/>
		<body name="torso" pos="0 0 1.4" >     
			<joint name="root" type="free" pos="0 0 0" limtype="0"/>
			<geom name="torso1" type="capsule" fromto="0 -.07 0 0 .07 0"  size="0.07" />
			<geom name="head" type="sphere" pos="0 0 .19" size=".09" />
			<geom name="uwaist" type="capsule" fromto="0 -.06 -.12 0 .06 -.12"  size="0.06" />
			<body name="pelvis" pos="0 0 -0.425" quat="1.000 0 -0.002 0" viscscale="1">
				<joint name="abdomen_y" type="hinge" pos="0 0 0.22" axis="0 1 0" limit="-60 10"/>
				<joint name="abdomen_z" type="hinge" pos="0 0 0.22" axis="0 0 1" limit="-45 45"/>
				<joint name="abdomen_x" type="hinge" pos="0 0 0.22" axis="1 0 0" limit="-20 20"/>
				<geom name="lwaist" type="capsule" fromto="0 -.06 0.15 0 .06 0.15"  size="0.06" />
				<geom name="butt" type="capsule" fromto="-.02 -.07 0 -.02 .07 0"  size="0.09" />
				<body name="right_thigh" pos="0 -0.1 -0.04" >
					<joint name="right_hip1" type="hinge" pos="0 0 0" axis="1 0 0" limit="-25 5"/>
					<joint name="right_hip2" type="hinge" pos="0 0 0" axis="0 0 1" limit="-60 35"/>
					<joint name="right_hip3" type="hinge" pos="0 0 0" axis="0 1 0" limit="-110 10"/>
					<geom name="right_thigh1" type="capsule" fromto="0 0 0 0 0.01 -.34"  size="0.065" />
					<body name="right_shin" pos="0 0.01 -0.403" >
						<joint name="right_knee" type="hinge" pos="0 0 .05" axis="0 -1 0" limit="-160 -5"/>
						<geom name="right_shin1" type="capsule" fromto="0 0 0 0 0 -.362"   size="0.049" />
						<body name="right_foot" pos="0 0 -.45" >
							<joint name="right_ankle" type="hinge" pos="0 0 0.06" axis="0 1 0" limit="-50 50"/>
							<geom name="right_foot_cap1" type="capsule" fromto="-.07 -0.02 0 0.14 -0.04 0"  size="0.027" />
							<geom name="right_foot_cap2" type="capsule" fromto="-.07 0 0 0.14  0.02 0"  size="0.027" />
						</body>
					</body>
				</body>
				<body name="left_thigh" pos="0 0.1 -0.04" >
					<joint name="left_hip1" type="hinge" pos="0 0 0" axis="-1 0 0" limit="-25 5"/>
					<joint name="left_hip2" type="hinge" pos="0 0 0" axis="0 0 -1" limit="-60 35"/>
					<joint name="left_hip3" type="hinge" pos="0 0 0" axis="0 1 0" limit="-110 10"/>
					<geom name="left_thigh1" type="capsule" fromto="0 0 0 0 -0.01 -.34"  size="0.065" />
					<body name="left_shin" pos="0 -0.01 -0.403" >
						<joint name="left_knee" type="hinge" pos="0 0 .05" axis="0 -1 0" limit="-160 -5"/>
						<geom name="left_shin1" type="capsule" fromto="0 0 0 0 0 -.362"   size="0.049" />
						<body name="left_foot" pos="0 0 -.45" >
							<joint name="left_ankle" type="hinge" pos="0 0 0.06" axis="0 1 0" limit="-50 50"/>
							<geom name="left_foot_cap1" type="capsule" fromto="-.07 0.02 0 0.14 0.04 0"  size="0.027" />
							<geom name="left_foot_cap2" type="capsule" fromto="-.07 0 0 0.14  -0.02 0"  size="0.027" />
						</body>
					</body> 
				</body>
			</body>
			<body name="right_upper_arm" pos="0 -0.17 0.06" >
				<joint name="right_shoulder1" type="hinge" pos="0 0 0" axis="0 -1 1" limit="-60 45"/>
				<joint name="right_shoulder2" type="hinge" pos="0 0 0" axis="2 1 1" limit="-45 45"/>
				<geom name="right_uarm1" type="capsule" fromto="0 0 0 .16 -.16 -.16"  size="0.04 0.16" />
				<body name="right_lower_arm" pos=".18 -.18 -.18" >
					<joint name="right_elbow" type="hinge" pos="0 0 0" axis="0 -1 1" limit="-90 50"/>
					<geom name="right_larm" type="capsule" fromto="0 0 0 .17 .17 .17"  size="0.031" />
				</body>
			</body>
			<body name="left_upper_arm" pos="0 0.17 0.06" >
				<joint name="left_shoulder1" type="hinge" pos="0 0 0" axis="0 1 1" limit="-60 45"/>
				<joint name="left_shoulder2" type="hinge" pos="0 0 0" axis="2 -1 1" limit="-45 45"/>
				<geom name="left_uarm1" type="capsule" fromto="0 0 0 .16 .16 -.16"  size="0.04 0.16" />
				<body name="left_lower_arm" pos=".18 .18 -.18" >
					<joint name="left_elbow" type="hinge" pos="0 0 0" axis="0 -1 -1" limit="-90 50"/>
					<geom name="left_larm" type="capsule" fromto="0 0 0 .17 -.17 .17"  size="0.031" />
				</body>
			</body>
		</body>
	</world>
	<actuator>
		<motor name="a_abdomen_y"		joint="abdomen_y"	gear="200"/>
		<motor name="a_abdomen_z"		joint="abdomen_z"	gear="200"/>
		<motor name="a_abdomen_x"		joint="abdomen_x"	gear="200"/>
		<motor name="a_right_hip1"		joint="right_hip1"	gear="200"/>
		<motor name="a_right_hip2"		joint="right_hip2"	gear="200"/>
		<motor name="a_right_hip3"		joint="right_hip3"	gear="400"/>
		<motor name="a_right_knee"		joint="right_knee"	gear="400"/>
		<motor name="a_right_ankle"		joint="right_ankle" gear="100"/>
		<motor name="a_left_hip1"		joint="left_hip1"	gear="200"/>
		<motor name="a_left_hip2"		joint="left_hip2"	gear="200"/>
		<motor name="a_left_hip3"		joint="left_hip3"	gear="400"/>
		<motor name="a_left_knee"		joint="left_knee"	gear="400"/>
		<motor name="a_left_ankle"		joint="left_ankle"	gear="100"/>
		<motor name="a_right_shoulder1"	joint="right_shoulder1" gear="100"/>
		<motor name="a_right_shoulder2"	joint="right_shoulder2" gear="100"/>
		<motor name="a_right_elbow"		joint="right_elbow"	gear="100"/>
		<motor name="a_left_shoulder1"	joint="left_shoulder1" gear="100"/>
		<motor name="a_left_shoulder2"	joint="left_shoulder2" gear="100"/>
		<motor name="a_left_elbow"		joint="left_elbow"	gear="100"/>
	</actuator>
</mujoco>
