<mujoco version="1.0">
	<compiler inertiafromgeom="true" maxjacobian="200" maxcontact="150"/>
	<engine gravity="0 0 -9.81" integrator="interleave" timestep="0.001" softclamp="0" sclsoftness="0.001 0.001"
		imperrreduce="0.001" algorithm="GS" atype="full" maxiter="5" viscosity="1"/>
	<default>
		<geom contype="1" condim="3" colmask="0 1" mindist="0.001" rgba=".9 .5 .8 1" friction=".7 .1 .1"/>
		<joint limtype="1" damping=".0001"/>
	</default>

	<world angle="degree" coordinate="local">
	
		<geom type="plane" pos="0.15 0 -0.03" size="1 1 3" rgba=".6 .6 .5 1" colmask="1 0" />

		<!--  ================= ARM ================= /-->
		
		<body name="link1" pos="0 0 1">
			<geom type="capsule" fromto="0 0 0 0.5 0.5 0" size="0.05"/>
			<joint type="free" pos="0 0 0" limtype="0"/>
			
			<body name="link2" pos="0.5 0.5 0">
				<geom type="capsule" fromto="0 0 0 0 0.5 0" size="0.05"/>
				<joint type="hinge" pos="0 0 0" axis="0 0 1" limit="-90 90"/>
				<joint type="hinge" pos="0 0 0" axis="1 0 0" limit="-90 90"/>
				<body name="link3" pos="0 0.5 0">
					<geom type="capsule" fromto="0 0 0 -0.5 0 0" size="0.05"/>
					<joint type="hinge" pos="0 0 0" axis="0 0 1" limit="-90 90"/>
					<joint type="hinge" pos="0 0 0" axis="0 1 0" limit="-90 90"/>
					<body name="link4" pos="-0.5 0 0">
						<geom type="capsule" fromto="0 0 0 0 -0.5 0" size="0.05"/>
						<joint type="hinge" pos="0 0 0" axis="0 0 1" limit="-90 90"/>
						<joint type="hinge" pos="0 0 0" axis="1 0 0" limit="-90 90"/>
						<body name="link5" pos="0 -0.5 0">
							<geom type="capsule" fromto="0 0 0 -0.5 0 0" size="0.05"/>
							<joint type="hinge" pos="0 0 0" axis="0 0 1" limit="-90 90"/>
							<joint type="hinge" pos="0 0 0" axis="0 1 0" limit="-90 90"/>
							<body name="link6" pos="-0.5 0 0">
								<geom type="capsule" fromto="0 0 0 0.5 -0.5 0" size="0.05"/>
								<joint type="hinge" pos="0 0 0" axis="0 0 1" limit="-90 90"/>
								<joint type="hinge" pos="0 0 0" axis="1 1 0" limit="-90 90"/>
							</body>
						</body>
					</body>
				</body>
			</body>
		</body>
	</world>
	<constraint>
		<point body1="link1" pos1="0 0 0" body2="link6" pos2="0.5 -0.5 0"/>
	</constraint>	
	
</mujoco>
