<mujoco version="1.0">
    <compiler uniquevertex="false" />
    <engine modelname="Rhesus Arm" timestep="0.001" gravity="0 0 -9.81" viscosity="0" wind="0 0 0" eqerrreduce="0.01" imperrreduce="0.01" eqsoftweight="100" softclamp="0" sclsoftness="1 1" sclmindist="1" expdist="3" integrator="semiimplicit" collisionmode="broadphase" eqsoft="false" consolidate="false" remotecontact="false" algorithm="GS" atype="full" maxiter="5" />
    <world coordinate="local" angle="radian" meshdir="Meshes/">
        <body name="prepelvis" pos="0 0 0" quat="0.70710678 0.70710678 0 0" viscscale="1">
            <inertial pos="0 0 0" mass="0.000001" inertia="0 0 0" />
            <joint name="lower_torso_TZ_root" type="free" limtype="0" pos="0 0 0" axis="0 0 1" />
            <body name="pelvis" pos="0 0 0" viscscale="1">
                <inertial pos="-0.0893 -0.025796 0" mass="8.3775" inertia="0.053993 0.061279 0.067263" />
                <body name="lumbar" pos="-0.043398 0.012031 0" viscscale="1">
                    <inertial pos="0.0145 0.075 0" mass="7.5375" inertia="0.014659 0.009207 0.019836" />
                    <joint name="lumbar_pitch" type="hinge" limtype="0" pos="0 0 0" axis="0 0 1" />
                    <joint name="lumbar_roll" type="hinge" limtype="0" pos="0 0 0" axis="1 0 0" />
                    <joint name="lumbar_yaw" type="hinge" limtype="0" pos="0 0 0" axis="0 1 0" />
                    <body name="torso" pos="-0.004536 0.057536 0" viscscale="1">
                        <inertial pos="0.0145 0.152288 0" mass="16.68" inertia="0.137572 0.086407 0.18616" />
                        <body name="clavicler" pos="0.014314 0.102024 0.010345" viscscale="1">
                            <inertial pos="0 0 0" mass="0.000001" inertia="0 0 0" />
                            <joint name="sternoclavicular_r_r2" type="hinge" pos="0 0 0" axis="0.01530000 0.98929870 -0.14509996" limit="-99999.9 99999.9" softness="0.0001" mindist="0.01" />
                            <joint name="sternoclavicular_r_r3" type="hinge" pos="0 0 0" axis="-0.99447254 0 -0.10499695" limit="-99999.9 99999.9" softness="0.0001" mindist="0.01" />
                            <body name="shouldermarkerr" pos="-0.010714 0.0125 -0.010344" viscscale="1">
                                <inertial pos="0 0 0" mass="0.000001" inertia="0 0 0" />
                            </body>
                            <body name="clavphantr" pos="-0.005809 0.008135 0.055061" viscscale="1">
                                <inertial pos="0 0 0" mass="0.000001" inertia="0 0 0" />
                                <joint name="unrotscap_r_r3" type="hinge" pos="0 0 0" axis="-0.99447254 0 -0.10499695" limit="-99999.9 99999.9" softness="0.0001" mindist="0.01" />
                                <joint name="unrotscap_r_r2" type="hinge" pos="0 0 0" axis="0.01530000 0.98929870 -0.14509996" limit="-99999.9 99999.9" softness="0.0001" mindist="0.01" />
                                <body name="scapular" pos="0 0 0" viscscale="1">
                                    <inertial pos="0 0 0" mass="0.000001" inertia="0 0 0" />
                                    <joint name="acromioclavicular_r_r2" type="hinge" pos="0 0 0" axis="0.15709493 0.94726859 -0.27929088" limit="-99999.9 99999.9" softness="0.0001" mindist="0.01" />
                                    <joint name="acromioclavicular_r_r3" type="hinge" pos="0 0 0" axis="-0.75408404 0.29759402 0.58548703" limit="-99999.9 99999.9" softness="0.0001" mindist="0.01" />
                                    <joint name="acromioclavicular_r_r1" type="hinge" pos="0 0 0" axis="0.63769985 0.11859997 0.76109982" limit="-99999.9 99999.9" softness="0.0001" mindist="0.01" />
                                    <body name="scapphantr" pos="-0.003871 -0.013782 0.003656" viscscale="1">
                                        <inertial pos="0 0 0" mass="0.000001" inertia="0 0 0" />
                                        <joint name="unrothum_r_r1" type="hinge" pos="0 0 0" axis="0.63769985 0.11859997 0.76109982" limit="-99999.9 99999.9" softness="0.0001" mindist="0.01" />
                                        <joint name="unrothum_r_r3" type="hinge" pos="0 0 0" axis="-0.75408404 0.29759402 0.58548703" limit="-99999.9 99999.9" softness="0.0001" mindist="0.01" />
                                        <joint name="unrothum_r_r2" type="hinge" pos="0 0 0" axis="0.15709493 0.94726859 -0.27929088" limit="-99999.9 99999.9" softness="0.0001" mindist="0.01" />
                                        <body name="humphantr" pos="0 0 0" viscscale="1">
                                            <inertial pos="0 0 0" mass="0.000001" inertia="0 0 0" />
                                            <joint name="elevation_angle_r" type="hinge" pos="0 0 0" axis="0.00480000 0.99908918 0.04240001" limit="-1.57079633 3.83972435" softness="0.0001" mindist="0.01" />
                                            <body name="humphant1r" pos="0 0 0" viscscale="1">
                                                <inertial pos="0 0 0" mass="0.000001" inertia="0 0 0" />
                                                <joint name="shoulder_elevation_r" type="hinge" pos="0 0 0" axis="-0.99826136 0.00230000 0.05889802" limit="0 3.14159265" softness="0.0001" mindist="0.01" />
                                                <joint name="shoulder1_r_r2" type="hinge" pos="0 0 0" axis="0.00480000 0.99908918 0.04240001" limit="-99999.9 99999.9" softness="0.0001" mindist="0.01" />
                                                <body name="humerusr" pos="0 0 0" viscscale="1">
                                                    <inertial pos="0 -0.081501 0" mass="2.0325" inertia="0.002932 0.001012 0.003291" />
                                                    <joint name="shoulder_rotation_r" type="hinge" pos="0 0 0" axis="0.00480000 0.99908918 0.04240001" limit="-1.57079633 2.09439510" softness="0.0001" mindist="0.01" />
                                                    <body name="elbowmarkerr" pos="0 0 0" quat="0.99973860 0.02001526 0.00044540 0.01104178" viscscale="1">
                                                        <inertial pos="0 0 0" mass="0.000001" inertia="0 0 0" />
                                                    </body>
                                                    <body name="ulnar" pos="0.004 -0.141 -0.005" viscscale="1">
                                                        <inertial pos="0.00483735 -0.0707474 0.0350708" mass="2.11654033" inertia="0.00355656 0.00074392 0.00385719" />
                                                        <joint name="elbow_flexion_r" type="hinge" pos="0 0 0" axis="0.04940001 0.03660001 0.99810825" limit="0 2.26892803" softness="0.0001" mindist="0.01" />
                                                        <body name="radiusr" pos="0.0004 -0.007 0.012" viscscale="1">
                                                            <inertial pos="0.00604668 -0.0707474 0.0120934" mass="2.11654033" inertia="0.00355656 0.00074392 0.00385719" />
                                                            <joint name="pro_supination_r" type="hinge" pos="0 0 0" axis="-0.01716099 0.99266564 -0.11966796" limit="-1.04719755 1.04719755" softness="0.0001" mindist="0.01" />
                                                            <body name="wristmarkerr" pos="-0.0004 0.011503 -0.02" quat="0.70613772 -0.09841024 0.70022527 -0.03700711" viscscale="1">
                                                                <inertial pos="0 0 0" mass="0.000001" inertia="0 0 0" />
                                                            </body>
                                                            <body name="workaroundr" pos="0 0 0" viscscale="1">
                                                                <inertial pos="0 0 0" mass="0.00000348" inertia="0 0 0" />
                                                                <joint name="wrist_flexion_r" type="hinge" pos="0 0 0" axis="1 0 0" limit="-1.22173048 1.22173048" softness="0.0001" mindist="0.01" />
                                                                <joint name="wrist_deviation_r" type="hinge" pos="0 0 0" axis="0 1 0" limit="-0.43633231 0.61086524" softness="0.0001" mindist="0.01" />
                                                            </body>
                                                            <body name="wristproxr" pos="0 -0.125 0.013" viscscale="1">
                                                                <inertial pos="0 0 0" mass="0.00536266" inertia="0.00001676 0.00001676 0.00001676" />
                                                                <joint name="radius_wrist_prox_r_r1" type="hinge" pos="0 0 0" axis="-0.81906400 -0.13561100 -0.55744400" limit="-99999.9 99999.9" softness="0.0001" mindist="0.01" />
                                                                <joint name="radius_wrist_prox_r_r3" type="hinge" pos="0 0 0" axis="0.95642673 -0.25220693 0.14710396" limit="-99999.9 99999.9" softness="0.0001" mindist="0.01" />
                                                                <body name="wristdistalr" pos="0.003992 -0.0101 0.002327" viscscale="1">
                                                                    <inertial pos="0 0 0" mass="0.00715021" inertia="0.00001676 0.00001676 0.00001676" />
                                                                    <joint name="wrist_prox_distal_r_r1" type="hinge" pos="0 0 0" axis="0.89913570 -0.34905288 -0.26403991" limit="-99999.9 99999.9" softness="0.0001" mindist="0.01" />
                                                                    <joint name="wrist_prox_distal_r_r3" type="hinge" pos="0 0 0" axis="0.99711853 0.01069999 -0.07510096" limit="-99999.9 99999.9" softness="0.0001" mindist="0.01" />
                                                                    <body name="trapeziumprer" pos="0.0093 -0.002 -0.0033" quat="0.71807589 0.01755425 0.62841994 0.29857535" viscscale="1">
                                                                        <inertial pos="0 0 0" mass="0.00000179" inertia="0 0 0" />
                                                                        <body name="trapeziumr" pos="0 0 0" quat="0.99315894 -0.00547060 -0.10438521 -0.05204925" viscscale="1">
                                                                            <inertial pos="0 0 0" mass="0.00178755" inertia="0.00001675 0.00001675 0.00001675" />
                                                                            <body name="thumbprer" pos="0 0 0" viscscale="1">
                                                                                <inertial pos="0 0 0" mass="0.000001" inertia="0 0 0" />
                                                                                <joint name="thumb_prox_flexion_r" type="hinge" pos="0 0 0" axis="0.95782623 0.28734807 0" limit="-0.78539816 0.52359878" softness="0.0001" mindist="0.01" />
                                                                                <body name="thumbproxr" pos="0.001 -0.0065 0.001" viscscale="1">
                                                                                    <inertial pos="0.00784 -0.01472 -0.00602" mass="0.016" inertia="0.00000119 0.00000071 0.00000126" />
                                                                                    <joint name="thumb_prox_abduction_r" type="hinge" pos="0 0 0" axis="0 0.51449590 0.85749284" limit="-0.61086524 0.61086524" softness="0.0001" mindist="0.01" />
                                                                                    <body name="thumbmidr" pos="0.0005 -0.02 0" viscscale="1">
                                                                                        <inertial pos="0 -0.018 -0.004" mass="0.0079" inertia="0.00000026 0.00000016 0.00000029" />
                                                                                        <joint name="thumb_mid_flexion_r" type="hinge" pos="0 0 0" axis="1 0 0" limit="-0.17453293 1.57079633" softness="0.0001" mindist="0.01" />
                                                                                        <body name="thumbdistalr" pos="-0.0005 -0.0135 0" viscscale="1">
                                                                                            <inertial pos="-0.0005 -0.01 -0.004" mass="0.0031" inertia="0 0 0" />
                                                                                            <joint name="thumb_distal_flexion_r" type="hinge" pos="0 0 0" axis="1 0 0" limit="-0.17453293 1.57079633" softness="0.0001" mindist="0.01" />
                                                                                        </body>
                                                                                    </body>
                                                                                </body>
                                                                            </body>
                                                                        </body>
                                                                    </body>
                                                                    <body name="palmr" pos="0.000477 -0.039239 0.007377" viscscale="1">
                                                                        <inertial pos="-0.0065 0 -0.004" mass="0.33243" inertia="0.00011 0.00006 0.00015" />
                                                                    </body>
                                                                    <body name="indexprer" pos="0.0075 -0.005 0.003" quat="0.99358663 -0.07174313 -0.08509458 0.01993622" viscscale="1">
                                                                        <inertial pos="0 0 0" mass="0.000001" inertia="0 0 0" />
                                                                        <body name="indexmetacarpalr" pos="0 0 0" viscscale="1">
                                                                            <inertial pos="0 0 0" mass="0.000001" inertia="0 0 0" />
                                                                            <body name="indexproxr" pos="0 -0.035 0.0005" viscscale="1">
                                                                                <inertial pos="0.001 -0.025 -0.003" mass="0.0158" inertia="0.00000121 0.00000028 0.00000120" />
                                                                                <joint name="index_prox_flexion_r" type="hinge" pos="0 0 0" axis="1 0 0" limit="-0.78539816 1.57079633" softness="0.0001" mindist="0.01" />
                                                                                <joint name="index_prox_abduction_r" type="hinge" pos="0 0 0" axis="0 0 1" limit="-0.78539816 0.78539816" softness="0.0001" mindist="0.01" />
                                                                                <body name="indexmidr" pos="0.002 -0.023 -0.0004" viscscale="1">
                                                                                    <inertial pos="0 -0.0178862 -0.00476965" mass="0.00875900" inertia="0.00000024 0 0.00000024" />
                                                                                    <joint name="index_mid_flexion_r" type="hinge" pos="0 0 0" axis="0.98058071 0 0.19611594" limit="-0.17453293 2.09439510" softness="0.0001" mindist="0.01" />
                                                                                    <body name="indexdistalr" pos="0 -0.014905 -0.002385" viscscale="1">
                                                                                        <inertial pos="0 -0.0130105 -0.00390314" mass="0.00321759" inertia="0 0 0" />
                                                                                        <joint name="index_distal_flexion_r" type="hinge" pos="0 0 0" axis="0.98058071 0 0.19611594" limit="-0.17453293 1.57079633" softness="0.0001" mindist="0.01" />
                                                                                    </body>
                                                                                </body>
                                                                            </body>
                                                                        </body>
                                                                    </body>
                                                                    <body name="middleprer" pos="0.001 -0.005 0.0025" quat="0.99752607 -0.06975382 0.00060874 0.00870528" viscscale="1">
                                                                        <inertial pos="0 0 0" mass="0.00000179" inertia="0 0 0" />
                                                                        <body name="middleproxr" pos="0 -0.039418 0" viscscale="1">
                                                                            <inertial pos="0.00111898 -0.0290935 -0.00447593" mass="0.03449975" inertia="0.00000295 0.00000052 0.00000294" />
                                                                            <joint name="middle_prox_flexion_r" type="hinge" pos="0 0 0" axis="1 0 0" limit="-0.78539816 1.57079633" softness="0.0001" mindist="0.01" />
                                                                            <joint name="middle_prox_abduction_r" type="hinge" pos="0 0 0" axis="0 0 1" limit="-0.43633231 0.43633231" softness="0.0001" mindist="0.01" />
                                                                            <body name="middlemidr" pos="0 -0.028 -0.0015" viscscale="1">
                                                                                <inertial pos="0.00096814 -0.0164584 -0.00387258" mass="0.01147608" inertia="0.00000044 0 0.00000044" />
                                                                                <joint name="middle_mid_flexion_r" type="hinge" pos="0 0 0" axis="0.98058071 0 0.19611594" limit="-0.17453293 2.09439510" softness="0.0001" mindist="0.01" />
                                                                            </body>
                                                                        </body>
                                                                    </body>
                                                                    <body name="ringprer" pos="-0.005 -0.006 0.0012" quat="0.99525071 -0.05905635 -0.07119668 -0.03032155" viscscale="1">
                                                                        <inertial pos="0 0 0" mass="0.00000179" inertia="0 0 0" />
                                                                        <body name="ringmetacarpalr" pos="0 0 0" quat="0.99935277 0.03489817 0.00030455 -0.00872122" viscscale="1">
                                                                            <inertial pos="0 0 0" mass="0.00000179" inertia="0 0 0" />
                                                                            <body name="ringproxr" pos="0 -0.037906 0.001132" viscscale="1">
                                                                                <inertial pos="0 -0.0264038 -0.00440064" mass="0.02456096" inertia="0.00000164 0.00000030 0.00000166" />
                                                                                <joint name="ring_prox_flexion_r" type="hinge" pos="0 0 0" axis="1 0 0" limit="-0.78539816 1.57079633" softness="0.0001" mindist="0.01" />
                                                                                <joint name="ring_prox_abduction_r" type="hinge" pos="0 0 0" axis="0 0 1" limit="-0.43633231 0.43633231" softness="0.0001" mindist="0.01" />
                                                                                <body name="ringmidr" pos="-0.0006 -0.028 0.001" viscscale="1">
                                                                                    <inertial pos="-0.00116243 -0.0174364 -0.00464971" mass="0.01015329" inertia="0.00000030 0 0.00000030" />
                                                                                    <joint name="ring_mid_flexion_r" type="hinge" pos="0 0 0" axis="0.98058071 0 0.19611594" limit="-0.17453293 2.09439510" softness="0.0001" mindist="0.01" />
                                                                                    <body name="ringdistalr" pos="0 -0.0172 -0.002" viscscale="1">
                                                                                        <inertial pos="0 -0.01 -0.003" mass="0.0029" inertia="0 0 0" />
                                                                                        <joint name="ring_distal_flexion_r" type="hinge" pos="0 0 0" axis="0.98058071 0 0.19611594" limit="-0.17453293 1.57079633" softness="0.0001" mindist="0.01" />
                                                                                    </body>
                                                                                </body>
                                                                            </body>
                                                                        </body>
                                                                    </body>
                                                                    <body name="pinkyprer" pos="-0.01 -0.006 -0.0007" quat="0.98747661 -0.06989254 -0.11801719 -0.07795460" viscscale="1">
                                                                        <inertial pos="0 0 0" mass="0.00000179" inertia="0 0 0" />
                                                                        <body name="pinkymetacarpalr" pos="0 0 0" quat="0.99687937 0.07845611 0.00068468 -0.00869963" viscscale="1">
                                                                            <inertial pos="0 0 0" mass="0.00000179" inertia="0 0 0" />
                                                                            <body name="pinkyproxr" pos="0 -0.033208 0.002214" viscscale="1">
                                                                                <inertial pos="0 -0.0234093 -0.00425624" mass="0.01977032" inertia="0.00000108 0.00000022 0.00000108" />
                                                                                <joint name="pinky_prox_flexion_r" type="hinge" pos="0 0 0" axis="1 0 0" limit="-0.78539816 1.57079633" softness="0.0001" mindist="0.01" />
                                                                                <joint name="pinky_prox_abduction_r" type="hinge" pos="0 0 0" axis="0 0 1" limit="-0.78539816 0.78539816" softness="0.0001" mindist="0.01" />
                                                                                <body name="pinkymidr" pos="0 -0.027134 -0.000532" viscscale="1">
                                                                                    <inertial pos="0 -0.0125859 -0.00387258" mass="0.00664969" inertia="0.00000014 0 0.00000014" />
                                                                                    <joint name="pinky_mid_flexion_r" type="hinge" pos="0 0 0" axis="0.98058071 0 0.19611594" limit="-0.17453293 2.09439510" softness="0.0001" mindist="0.01" />
                                                                                    <body name="pinkydistalr" pos="0.000678 -0.013554 -0.001743" viscscale="1">
                                                                                        <inertial pos="0 -0.0121659 -0.00405531" mass="0.00396836" inertia="0 0 0" />
                                                                                        <joint name="pinky_distal_flexion_r" type="hinge" pos="0 0 0" axis="0.98058071 0 0.19611594" limit="-0.17453293 1.57079633" softness="0.0001" mindist="0.01" />
                                                                                    </body>
                                                                                </body>
                                                                            </body>
                                                                        </body>
                                                                    </body>
                                                                </body>
                                                            </body>
                                                        </body>
                                                    </body>
                                                </body>
                                            </body>
                                        </body>
                                    </body>
                                </body>
                            </body>
                        </body>
                    </body>
                </body>
            </body>
        </body>
    </world>
</mujoco>
