<!-- vim: set ts=4 sw=4 expandtab : -->
<mujoco version="1.0">
	<compiler uniquevertex="false" inertiafromgeom="true"/>
    <default>
        <!--        <body viscscale="1"/> -->
        <geom contype="0" friction="1 0.1 0.1" rgba="0.7 0.7 0 1" colmask="0 1" density="8000"/>
        <joint  damping=".01" limtype="1" maxvel="1000" softness="0.0001" mindist="0.01" />
        <!-- <actuator range="-1 1" dyntype="none" trntype="joint" gaintype="fixed" dynprm="0 0" trnprm="10000" gainprm="1" /> -->
    </default>    
	<engine modelname="Rhesus Arm" timestep="0.001" gravity="0 0 0" viscosity="0" wind="0 0 0" eqerrreduce="0.01" imperrreduce="0.01" eqsoftweight="100" softclamp="0" sclsoftness="1 1" sclmindist="1" expdist="3" integrator="semiimplicit" collisionmode="broadphase" eqsoft="false" consolidate="false" remotecontact="false" algorithm="GS" atype="full" maxiter="5" />
	<world coordinate="local" angle="radian" meshdir="Meshes/">
		<geom name="floor" pos="0 0 -.3" size="10 10 40" type="plane" rgba=".8 .9 .8 1" condim="3" />
		<body name="prepelvis" pos="0 0 0" quat="0.70710678 0.70710678 0 0" >
			<!-- <joint name="lower_torso_TZ_root" type="free" limtype="0" pos="0 0 0" axis="0 0 1" /> -->
			<body name="pelvis" pos="0 0 0" >
				<geom type="capsule" fromto="0 0 0 -0.043398 0.012031 0" size="0.005" rgba=".3 .5 .8 1" />
				<body name="lumbar" pos="-0.043398 0.012031 0" >
					<geom type="capsule" fromto="0 0 0 -0.004536 0.057536 0" size="0.005" rgba=".3 .5 .8 1" />
					<!-- <joint name="lumbar_pitch" type="hinge" limtype="0" pos="0 0 0" axis="0 0 1" /> -->
					<!-- <joint name="lumbar_roll" type="hinge" limtype="0" pos="0 0 0" axis="1 0 0" /> -->
					<!-- <joint name="lumbar_yaw" type="hinge" limtype="0" pos="0 0 0" axis="0 1 0" /> -->
					<body name="torso" pos="-0.004536 0.057536 0" >
						<geom type="capsule" fromto="0 0 0 0.014314 0.102024 0.010345" size="0.005" rgba=".3 .5 .8 1" />
						<body name="clavicler" pos="0.014314 0.102024 0.010345" >
							<geom type="capsule" fromto="0 0 0 -0.005809 0.008135 0.055061" size="0.005" rgba=".3 .5 .8 1" />
							<!-- <joint name="sternoclavicular_r_r2" limtype="0" type="hinge" pos="0 0 0" axis="0.01530000 0.98929870 -0.14509996" /> -->
							<!-- <joint name="sternoclavicular_r_r3" limtype="0" type="hinge" pos="0 0 0" axis="-0.99447254 0 -0.10499695" /> -->
							<body name="clavphantr" pos="-0.005809 0.008135 0.055061" >
								<!-- <joint name="unrotscap_r_r3" type="hinge" limtype="0" pos="0 0 0" axis="-0.99447254 0 -0.10499695" /> -->
								<!-- <joint name="unrotscap_r_r2" type="hinge" limtype="0" pos="0 0 0" axis="0.01530000 0.98929870 -0.14509996" /> -->
								<body name="scapular" pos="0 0 0" >
									<geom type="capsule" fromto="0 0 0 -0.003871 -0.013782 0.003656" size="0.005" rgba=".3 .5 .8 1" />
									<!-- <joint name="acromioclavicular_r_r2" type="hinge" pos="0 0 0" limtype="0" axis="0.15709493 0.94726859 -0.27929088" /> -->
									<!-- <joint name="acromioclavicular_r_r3" type="hinge" pos="0 0 0" limtype="0" axis="-0.75408404 0.29759402 0.58548703" /> -->
									<!-- <joint name="acromioclavicular_r_r1" type="hinge" pos="0 0 0" limtype="0" axis="0.63769985 0.11859997 0.76109982" /> -->
									<body name="scapphantr" pos="-0.003871 -0.013782 0.003656" >
										<!-- <joint name="unrothum_r_r1" type="hinge" pos="0 0 0" limtype="0" axis="0.63769985 0.11859997 0.76109982" /> -->
										<!-- <joint name="unrothum_r_r3" type="hinge" pos="0 0 0" limtype="0" axis="-0.75408404 0.29759402 0.58548703" /> -->
										<!-- <joint name="unrothum_r_r2" type="hinge" pos="0 0 0" limtype="0" axis="0.15709493 0.94726859 -0.27929088" /> -->
										<body name="humphantr" pos="0 0 0" >
											<joint name="elevation_angle_r" type="hinge" pos="0 0 0" axis="0.00480000 0.99908918 0.04240001" limit="-1.57079633 3.83972435" />
											<body name="humphant1r" pos="0 0 0" >
												<joint name="shoulder_elevation_r" type="hinge" pos="0 0 0" axis="-0.99826136 0.00230000 0.05889802" limit="0 3.14159265" />
												<!-- <joint name="shoulder1_r_r2" type="hinge" pos="0 0 0" limtype="0" axis="0.00480000 0.99908918 0.04240001" /> -->
												<body name="humerusr" pos="0 0 0" >
													<geom type="capsule" fromto="0 0 0 0.004 -0.141 -0.005" size="0.005" rgba=".3 .5 .8 1" />
													<joint name="shoulder_rotation_r" type="hinge" pos="0 0 0" axis="0.00480000 0.99908918 0.04240001" limit="-1.57079633 2.09439510" />
													<body name="ulnar" pos="0.004 -0.141 -0.005" >
														<geom type="capsule" fromto="0 0 0 0.0004 -0.007 0.012" size="0.005" rgba=".3 .5 .8 1" />
														<joint name="elbow_flexion_r" type="hinge" pos="0 0 0" axis="0.04940001 0.03660001 0.99810825" limit="0 2.26892803" />
														<body name="radiusr" pos="0.0004 -0.007 0.012" >
															<geom type="capsule" fromto="0 0 0 0 -0.125 0.013" size="0.005" rgba=".3 .5 .8 1" />
															<joint name="pro_supination_r" type="hinge" pos="0 0 0" axis="-0.01716099 0.99266564 -0.11966796" limit="-1.04719755 1.04719755" />
<!-- 															<body name="workaroundr" pos="0 0 0" >
																<joint name="wrist_flexion_r" type="hinge" pos="0 0 0" axis="1 0 0" limit="-1.22173048 1.22173048" />
																<joint name="wrist_deviation_r" type="hinge" pos="0 0 0" axis="0 1 0" limit="-0.43633231 0.61086524" />
															</body> -->
															<body name="wristproxr" pos="0 -0.125 0.013" >
																<geom type="capsule" fromto="0 0 0 0.003992 -0.0101 0.002327" size="0.005" rgba=".3 .5 .8 1" />
																<joint name="radius_wrist_prox_r_r1" type="hinge" limtype="0" pos="0 0 0" axis="-0.81906400 -0.13561100 -0.55744400" />
																<joint name="radius_wrist_prox_r_r3" type="hinge" limtype="0" pos="0 0 0" axis="0.95642673 -0.25220693 0.14710396" />
																<body name="wristdistalr" pos="0.003992 -0.0101 0.002327" >
																	<geom type="capsule" fromto="0 0 0 0.0093 -0.002 -0.0033" size="0.005" rgba=".3 .5 .8 1" />
																	<joint name="wrist_prox_distal_r_r1" type="hinge" limtype="0" pos="0 0 0" axis="0.89913570 -0.34905288 -0.26403991" />
																	<joint name="wrist_prox_distal_r_r3" type="hinge" limtype="0" pos="0 0 0" axis="0.99711853 0.01069999 -0.07510096" />
																	<body name="trapeziumprer" pos="0.0093 -0.002 -0.0033" quat="0.71807589 0.01755425 0.62841994 0.29857535" >
																		<geom type="capsule" fromto="0 0 0 0.001 -0.0065 0.001" size="0.005" rgba=".3 .5 .8 1" />
																		<body name="trapeziumr" pos="0 0 0" quat="0.99315894 -0.00547060 -0.10438521 -0.05204925" >
                                                                        <geom type="sphere" pos="0 0 0" size="0.005" rgba=".3 .5 .8 1" />
																			<body name="thumbprer" pos="0 0 0" >
                                                                                <geom type="sphere" pos="0 0 0" size="0.005" rgba=".3 .5 .8 1" />
																				<joint name="thumb_prox_flexion_r" type="hinge" pos="0 0 0" axis="0.95782623 0.28734807 0" limit="-0.78539816 0.52359878" />
																				<body name="thumbproxr" pos="0.001 -0.0065 0.001" >
																					<geom type="capsule" fromto="0 0 0 0.0005 -0.02 0" size="0.005" rgba=".3 .5 .8 1" />
																					<joint name="thumb_prox_abduction_r" type="hinge" pos="0 0 0" axis="0 0.51449590 0.85749284" limit="-0.61086524 0.61086524" />
																					<body name="thumbmidr" pos="0.0005 -0.02 0" >
																						<geom type="capsule" fromto="0 0 0 -0.0005 -0.0135 0" size="0.005" rgba=".3 .5 .8 1" />
																						<joint name="thumb_mid_flexion_r" type="hinge" pos="0 0 0" axis="1 0 0" limit="-0.17453293 1.57079633" />
																				<!-- 		<body name="thumbdistalr" pos="-0.0005 -0.0135 0" >
																							<joint name="thumb_distal_flexion_r" type="hinge" pos="0 0 0" axis="1 0 0" limit="-0.17453293 1.57079633" />
																						</body> -->
																					</body>
																				</body>
																			</body>
																		</body>
																	</body>
																	<geom type="capsule" fromto="0 0 0 0.000477 -0.039239 0.007377" size="0.005" rgba=".3 .5 .8 1" />
																<!-- 	<body name="palmr" pos="0.000477 -0.039239 0.007377" >
																	</body> -->
																	<geom type="capsule" fromto="0 0 0 0.0075 -0.005 0.003" size="0.005" rgba=".3 .5 .8 1" />
																	<body name="indexprer" pos="0.0075 -0.005 0.003" quat="0.99358663 -0.07174313 -0.08509458 0.01993622" >
                                                                        <geom type="sphere" pos="0 0 0" size="0.005" rgba=".3 .5 .8 1" />
																		<body name="indexmetacarpalr" pos="0 0 0" >
																			<geom type="capsule" fromto="0 0 0 0 -0.035 0.0005" size="0.005" rgba=".3 .5 .8 1" />
																			<body name="indexproxr" pos="0 -0.035 0.0005" >
																				<geom type="capsule" fromto="0 0 0 0.002 -0.023 -0.0004" size="0.005" rgba=".3 .5 .8 1" />
																				<joint name="index_prox_flexion_r" type="hinge" pos="0 0 0" axis="1 0 0" limit="-0.78539816 1.57079633" />
																				<joint name="index_prox_abduction_r" type="hinge" pos="0 0 0" axis="0 0 1" limit="-0.78539816 0.78539816" />
																				<body name="indexmidr" pos="0.002 -0.023 -0.0004" >
																					<geom type="capsule" fromto="0 0 0 0 -0.014905 -0.002385" size="0.005" rgba=".3 .5 .8 1" />
																					<joint name="index_mid_flexion_r" type="hinge" pos="0 0 0" axis="0.98058071 0 0.19611594" limit="-0.17453293 2.09439510" />
																					<body name="indexdistalr" pos="0 -0.014905 -0.002385" >
																						<joint name="index_distal_flexion_r" type="hinge" pos="0 0 0" axis="0.98058071 0 0.19611594" limit="-0.17453293 1.57079633" />
                                                                                        <geom type="capsule" fromto="0 0 0 0 -0.028 -0.0015" size="0.005" rgba=".3 .5 .8 1" />
																					</body>
																				</body>
																			</body>
																		</body>
																	</body>
																	<geom type="capsule" fromto="0 0 0 0.001 -0.005 0.0025" size="0.005" rgba=".3 .5 .8 1" />
																	<body name="middleprer" pos="0.001 -0.005 0.0025" quat="0.99752607 -0.06975382 0.00060874 0.00870528" >
																		<geom type="capsule" fromto="0 0 0 0 -0.039418 0" size="0.005" rgba=".3 .5 .8 1" />
																		<body name="middleproxr" pos="0 -0.039418 0" >
																			<geom type="capsule" fromto="0 0 0 0 -0.028 -0.0015" size="0.005" rgba=".3 .5 .8 1" />
																			<joint name="middle_prox_flexion_r" type="hinge" pos="0 0 0" axis="1 0 0" limit="-0.78539816 1.57079633" />
																			<joint name="middle_prox_abduction_r" type="hinge" pos="0 0 0" axis="0 0 1" limit="-0.43633231 0.43633231" />
                                                                            <body name="middlemidr" pos="0 -0.028 -0.0015" >
                                                                                <site name="finger" pos=" 0 -0.028 -0.0015" />
																				<joint name="middle_mid_flexion_r" type="hinge" pos="0 0 0" axis="0.98058071 0 0.19611594" limit="-0.17453293 2.09439510" />
                                                                                <geom type="capsule" fromto="0 0 0 0 -0.028 -0.0015" size="0.005" rgba=".3 .5 .8 1" />
																			</body>
																		</body>
																	</body>
																	<geom type="capsule" fromto="0 0 0 -0.005 -0.006 0.0012" size="0.005" rgba=".3 .5 .8 1" />
																	<body name="ringprer" pos="-0.005 -0.006 0.0012" quat="0.99525071 -0.05905635 -0.07119668 -0.03032155" >
                                                                        <geom type="sphere" pos="0 0 0" size="0.005" rgba=".3 .5 .8 1" />
																		<body name="ringmetacarpalr" pos="0 0 0" quat="0.99935277 0.03489817 0.00030455 -0.00872122" >
																			<geom type="capsule" fromto="0 0 0 0 -0.037906 0.001132" size="0.005" rgba=".3 .5 .8 1" />
																			<body name="ringproxr" pos="0 -0.037906 0.001132" >
																				<geom type="capsule" fromto="0 0 0 -0.0006 -0.028 0.001" size="0.005" rgba=".3 .5 .8 1" />
																				<joint name="ring_prox_flexion_r" type="hinge" pos="0 0 0" axis="1 0 0" limit="-0.78539816 1.57079633" />
																				<joint name="ring_prox_abduction_r" type="hinge" pos="0 0 0" axis="0 0 1" limit="-0.43633231 0.43633231" />
																				<body name="ringmidr" pos="-0.0006 -0.028 0.001" >
																					<geom type="capsule" fromto="0 0 0 0 -0.0172 -0.002" size="0.005" rgba=".3 .5 .8 1" />
																					<joint name="ring_mid_flexion_r" type="hinge" pos="0 0 0" axis="0.98058071 0 0.19611594" limit="-0.17453293 2.09439510" />
																	<!-- 				<body name="ringdistalr" pos="0 -0.0172 -0.002" >
																						<joint name="ring_distal_flexion_r" type="hinge" pos="0 0 0" axis="0.98058071 0 0.19611594" limit="-0.17453293 1.57079633" />
																					</body> -->
																				</body>
																			</body>
																		</body>
																	</body>
																	<!-- <geom type="capsule" fromto="0 0 0 -0.01 -0.006 -0.0007" size="0.005" rgba=".3 .5 .8 1" /> -->
																	<body name="pinkyprer" pos="-0.01 -0.006 -0.0007" quat="0.98747661 -0.06989254 -0.11801719 -0.07795460" >
                                                                        <geom type="sphere" pos="0 0 0" size="0.005" rgba=".3 .5 .8 1" />
																		<body name="pinkymetacarpalr" pos="0 0 0" quat="0.99687937 0.07845611 0.00068468 -0.00869963" >
																			<geom type="capsule" fromto="0 0 0 0 -0.033208 0.002214" size="0.002" rgba=".3 .5 .8 1" />
																			<body name="pinkyproxr" pos="0 -0.033208 0.002214" >
																				<geom type="capsule" fromto="0 0 0 0 -0.027134 -0.000532" size="0.002" rgba=".3 .5 .8 1" />
																				<joint name="pinky_prox_flexion_r" type="hinge" pos="0 0 0" axis="1 0 0" limit="-0.78539816 1.57079633" />
																				<joint name="pinky_prox_abduction_r" type="hinge" pos="0 0 0" axis="0 0 1" limit="-0.78539816 0.78539816" />
																				<body name="pinkymidr" pos="0 -0.027134 -0.000532" >
																					<geom type="capsule" fromto="0 0 0 0.000678 -0.013554 -0.001743" size="0.002" rgba=".3 .5 .8 1" />
																					<joint name="pinky_mid_flexion_r" type="hinge" pos="0 0 0" axis="0.98058071 0 0.19611594" limit="-0.17453293 2.09439510" />
																					<body name="pinkydistalr" pos="0.000678 -0.013554 -0.001743" >
                                                                                        <geom type="capsule" fromto="0 0 0 0.000678 -0.013554 -0.001743" size="0.002" rgba=".3 .5 .8 1" />
																						<joint name="pinky_distal_flexion_r" type="hinge" pos="0 0 0" axis="0.98058071 0 0.19611594" limit="-0.17453293 1.57079633" />
																					</body>
																				</body>
																			</body>
																		</body>
																	</body>
																</body>
															</body>
														</body>
													</body>
												</body>
											</body>
										</body>
									</body>
								</body>
							</body>
						</body>
					</body>
				</body>
			</body>
		</body>
                <!--  ================= TOY ================= /-->
                <body name="toy" pos="0.2 -0.15 0.2" quat="1 0.01 0.01 0" >
                        <geom type="capsule" fromto="-.03 0 0 .03 0 0" size="0.015" rgba=".3 .5 .8 1" />
                        <geom type="capsule" fromto="0 -.03 0 0 .03 0" size="0.015" rgba=".3 .5 .8 1" />
                        <geom type="capsule" fromto="0 0 -.03 0 0 .03" size="0.015" rgba=".3 .5 .8 1" />
                        <site name="point" pos="-.045 0 0" />
                        <joint name="free" type="free" pos="0 0 0" limtype="0" damping="0"/>
                        <body name="link1" pos="0.08 0 0"  >
                                <joint name="jlink1" type="ball" pos="-0.04 0 0" limtype="0"/>
                                <geom type="box" size=".03 0.01 0.01"  rgba=".3 .5 .8 1" />
                                <body name="link2" pos="0.08 0 0"  >
                                        <joint name="jlink2" type="ball" pos="-0.04 0 0" limtype="0"/>
                                        <geom type="box" size=".03 0.01 0.01"  rgba=".3 .5 .8 1" />
                                        <body name="link3" pos="0.08 0 0"  >
                                                <joint name="jlink3" type="ball" pos="-0.04 0 0" limtype="0"/>
                                                <geom type="box" size=".03 0.01 0.01"  rgba=".3 .5 .8 1" />
                                        </body>
                                </body>                         
                      </body>
         </body>         

    
    </world>

</mujoco>
